Workbook
Name _T01: #REF!

Sheet Chart
D2: CHART OF ACCOUNT
C4: Seg 1 | D4: Seg 2 | E4: Seg 3 | F4: Seg 4 | G4: Seg 5 | H4: Seg 6 | I4: Seg 7 | J4: Seg 8 | K4: Seg 9 | L4: Seg 10
C5: xx | D5: xxx.xx.xx | E5: xx.xxx | F5: x.xx | G5: xx.xx.xx | H5: xx.xx | I5: x.xx.xx | J5: xx | K5: xx | L5: xxxx
C14: LEGAL_ENITY | D14: ACCOUNT | E14: SUB_ACCOUNT | F14: COST CENTER | G14: BUSINESS_LINE | H14: BRAND | I14: CHANNEL | J14: INTERCOMPANY | K14: SITE | L14: RESERVE
B16: Số ký tự | C16: 2 | D16: 7 | E16: 5 | F16: 3 | G16: 6 | H16: 4 | I16: 5 | J16: 2 | K16: 2 | L16: 4
C17: 17 | D17: 4131101 | E17: 00000 | F17: 000 | G17: 000000 | H17: 0000 | I17: 00000 | J17: 00 | K17: 00 | L17: 0000
C18: 17 | D18: 1289999 | E18: ZZZZZ | F18: ZZZ | G18: ZZZZZZ | H18: ZZZZ | I18: ZZZZZ | J18: ZZ | K18: ZZ | L18: ZZZZ
C19: =CONCATENATE(C17,"-",D17,"-",E17,"-",F17,"-",G17,"-",H17,"-",I17,"-",J17,"-",K17,"-",L17) -> 17-4131101-00000-000-000000-0000-00000-00-00-0000 | N19: COA_LEGAL_ENITY
C20: =CONCATENATE(C18,"-",D18,"-",E18,"-",F18,"-",G18,"-",H18,"-",I18,"-",J18,"-",K18,"-",L18) -> 17-1289999-ZZZZZ-ZZZ-ZZZZZZ-ZZZZ-ZZZZZ-ZZ-ZZ-ZZZZ | N20: COA_ACCOUNT
B21: Cộng | C21: =SUM(C16:L16) -> 40 | N21: COA_SUB_ACCOUNT
N22: COA_COST_CENTER
B23: Proposed Chart of Accounts | N23: COA_BUSINESSLINE
N24: COA_BRAND
C25: Legal Entity | D25: Account | E25: Sub-Account | F25: Cost center | G25: Business Line | H25: Brand | I25: Channel | J25: Intercompany | K25: Site | L25: Reserve | N25: COA_CHANNEL
N26: COA_INTER_CO
B27: Exp1: | C27: Basis salary | N27: COA_SITE
B28: Segment name | C28: Legal Entity | D28: Account | E28: Sub-Account | F28: Cost center | G28: Business Line | H28: Brand | I28: Channel | J28: Intercompany | K28: Reserve | L28: Reserve | N28: COA_RESERVE
B29: Code | C29: 11 | D29: 642101 | E29: 3101 | F29: 103 | G29: 000 | H29: 000 | I29: 000 | J29: 00 | K29: 000 | L29: 000
B30: Description | C30: PartnerCompany | D30: Employees cost | E30: Basis salary | F30: Financial Accounting | G30: Default | H30: Default | I30: Default | J30: Default | K30: Default | L30: Default
B31: GL account | C31: 11.642101.3101.103.000.000.000.00.000
B33: Exp2: | C33: Receivable intercompany (PartnerCompany-DTC)
B34: Segment name | C34: Legal Entity | D34: Account | E34: Sub-Account | F34: Cost center | G34: Business Line | H34: Brand | I34: Channel | J34: Intercompany | K34: Reserve | L34: Reserve
B35: Code | C35: 11 | D35: 131101 | E35: 0000 | F35: 000 | G35: 000 | H35: 000 | I35: 000 | J35: 12 | K35: 000 | L35: 000
B36: Description | C36: PartnerCompany | D36: Trade account receivable | E36: Default | F36: Default | G36: Default | H36: Default | I36: Default | J36: DTC | K36: Default | L36: Default
B37: GL account | C37: 11.131101.0000.000.000.000.000.12.000
B39: Exp3: | C39: Revenue
B40: Segment name | C40: Legal Entity | D40: Account | E40: Sub-Account | F40: Cost center | G40: Business Line | H40: Brand | I40: Channel | J40: Intercompany | K40: Reserve | L40: Reserve
B41: Code | C41: 11 | D41: 511101 | E41: 0000 | F41: 000 | G41: 101 | H41: 101 | I41: 101 | J41: 00 | K41: 000 | L41: 000
B42: Description | C42: PartnerCompany | D42: Revenue | E42: Default | F42: Default | G42: Cake & Ice dream | H42: Korean | I42: Shop in shop | J42: Default | K42: Default | L42: Default
B43: GL account | C43: 11.511101.0000.000.101.101.101.00.000 | G43: Kem
C47: Budget | G47: PR/PO (Encumbrance) | K47: AP Invoice (N Actual/C Encumbrance) | O47: FA Asset
O48: Asset cost
B49: Summary | C49: Account | D49: Cost center | E49: Sub | G49: Account | H49: Cost center | I49: Sub | K49: Account | L49: Cost center | M49: Sub | O49: Account | P49: Cost center | Q49: Sub
B50: Kinh doanh. CAPEX | C50: 241101 | D50: HCM-Bộ phận Kinh doanh trực tiếp | E50: S&M (tủ đông) | F50: 90000000 | G50: 241101 | H50: HCM-Bộ phận Kinh doanh trực tiếp | I50: S&M (tủ đông) | J50: 100000000 | K50: 241101 | L50: HCM-Bộ phận Kinh doanh trực tiếp | M50: S&M (tủ đông) | O50: 242101 | P50: 0000 | Q50: 0000
C51: 241101 | D51: HCM-Bộ phận Kinh doanh trực tiếp | E51: LOG (xe tải, thiết bị máy móc…) | F51: 50000000 | G51: 241101 | H51: HCM-Bộ phận Kinh doanh trực tiếp | I51: LOG (xe tải, thiết bị máy móc…) | J51: 50000000 | K51: 241101 | L51: HCM-Bộ phận Kinh doanh trực tiếp | M51: LOG (xe tải, thiết bị máy móc…) | O51: 211101 | P51: 0000 | Q51: 0000
O53: Depriciation
O54: Account | P54: Cost center | Q54: Sub
O55: 641xxx | P55: HCM-Bộ phận logistic | Q55: Khấu hao/Máy móc, thiết bị
O56: 641xxx | P56: HCM-Bộ phận logistic | Q56: Khấu hao/Phương tiện vận tải

Sheet Seg 1_Công ty
A1: Segment 1 : xx (Công ty - Company)
A3: Mã | B3: Tên công ty | D3: Địa chỉ | E3: MST | F3: Tel | G3: Fax | H3: Ledger code | I3: OU code | J3: FA book | K3: Chủ tịch HĐQT | L3: KTT | M3: Tên kỳ
A4: 17 | M4: 01-2024

Sheet Seg 2_Account
A2: Segment 2 : xxx.xx.xx (Tài khoản - Account)
B4: Account code | F4: Account Name | G4: Level | H4: Parent | I4: BS Dr | J4: BS Cr | K4: ACCOUNT_TYPE | L4: THIRD_PARTY_CONTROL | M4: RECONCILE | N4: New
B5: =C5&D5&E5 -> 0000000 | C5: 000 | D5: 00 | E5: 00 | F5: Măc đinh | G5: 1
B6: =C6&D6&E6 -> 1110000 | C6: 111 | D6: 00 | E6: 00 | F6: Tiền Mặt | G6: 1 | H6: x | I6: BS111 | K6: Asset | M6: Y
B7: =C7&D7&E7 -> 1111000 | C7: 111 | D7: 10 | E7: 00 | F7: Tiền Mặt - VND | G7: 2 | H7: x | K7: Asset | M7: Y
B8: =C8&D8&E8 -> 1111101 | C8: 111 | D8: 11 | E8: 01 | F8: Tiền Mặt - VND | G8: 3 | K8: Asset | M8: Y
B9: =C9&D9&E9 -> 1112000 | C9: 111 | D9: 20 | E9: 00 | F9: Tiền mặt - Ngoại tệ | G9: 2 | H9: x | K9: Asset | M9: Y
B10: =C10&D10&E10 -> 1112101 | C10: 111 | D10: 21 | E10: 01 | F10: Tiền mặt - USD | G10: 3 | K10: Asset | M10: Y
B11: =C11&D11&E11 -> 1120000 | C11: 112 | D11: 00 | E11: 00 | F11: Tiền Gửi Ngân Hàng | G11: 1 | H11: x | I11: BS111 | K11: Asset | M11: Y
B12: =C12&D12&E12 -> 1121000 | C12: 112 | D12: 10 | E12: 00 | F12: Tiền gửi ngân hàng-VND | G12: 2 | H12: x | K12: Asset | M12: Y
B13: =C13&D13&E13 -> 1121101 | C13: 112 | D13: 11 | E13: 01 | F13: Tiền gửi ngân hàng-VND-VIETTINBANK | G13: 3 | K13: Asset | M13: Y
B14: =C14&D14&E14 -> 1121102 | C14: 112 | D14: 11 | E14: 02 | F14: Tiền gửi ngân hàng-VND-VIETCOMBANK | G14: 3 | K14: Asset | M14: Y
B15: =C15&D15&E15 -> 1122000 | C15: 112 | D15: 20 | E15: 00 | F15: Tiền gửi ngân hàng - Ngoại tệ | G15: 2 | H15: x | K15: Asset | M15: Y
B16: =C16&D16&E16 -> 1122101 | C16: 112 | D16: 21 | E16: 01 | F16: Tiền gửi ngân hàng-USD-VIETCOMBANK | G16: 3 | K16: Asset | M16: Y
B17: =C17&D17&E17 -> 1130000 | C17: 113 | D17: 00 | E17: 00 | F17: Tiền Đang Chuyển | G17: 1 | H17: x | I17: BS111 | K17: Asset
B18: =C18&D18&E18 -> 1131000 | C18: 113 | D18: 10 | E18: 00 | F18: Tiền đang chuyển-VND | G18: 2 | H18: x | K18: Asset
B19: =C19&D19&E19 -> 1131101 | C19: 113 | D19: 11 | E19: 01 | F19: Tiền đang chuyển giữa 2 tài khoản ngân hàng | G19: 3 | K19: Asset
B20: =C20&D20&E20 -> 1131102 | C20: 113 | D20: 11 | E20: 02 | F20: Tiền đang chuyển trong 1 tài khoản ngân hàng khi chưa đối soát | G20: 3 | K20: Asset
B21: =C21&D21&E21 -> 1132000 | C21: 113 | D21: 20 | E21: 00 | F21: Tiền đang chuyển-Ngoại tệ | G21: 2 | H21: x | K21: Asset
B22: =C22&D22&E22 -> 1132101 | C22: 113 | D22: 21 | E22: 01 | F22: Tiền đang chuyển-Ngoại tệ | G22: 3 | K22: Asset
B23: =C23&D23&E23 -> 1139000 | C23: 113 | D23: 90 | E23: 00 | F23: Trung gian tiền đang chuyển | G23: 2 | H23: x | K23: Asset
B24: =C24&D24&E24 -> 1139101 | C24: 113 | D24: 91 | E24: 01 | F24: Cash clearing | G24: 3 | K24: Asset
B25: =C25&D25&E25 -> 1210000 | C25: 121 | D25: 00 | E25: 00 | F25: Chứng khoán kinh doanh | G25: 1 | H25: x | I25: BS121 | K25: Asset
B26: =C26&D26&E26 -> 1211000 | C26: 121 | D26: 10 | E26: 00 | F26: Cổ phiếu | G26: 2 | H26: x | K26: Asset
B27: =C27&D27&E27 -> 1211101 | C27: 121 | D27: 11 | E27: 01 | F27: Cổ phiếu | G27: 3 | K27: Asset
B28: =C28&D28&E28 -> 1212000 | C28: 121 | D28: 20 | E28: 00 | F28: Trái phiếu | G28: 2 | H28: x | K28: Asset
B29: =C29&D29&E29 -> 1212101 | C29: 121 | D29: 21 | E29: 01 | F29: Trái phiếu | G29: 3 | K29: Asset
B30: =C30&D30&E30 -> 1218000 | C30: 121 | D30: 80 | E30: 00 | F30: Chứng khoán và công cụ tài chính khác | G30: 2 | H30: x | K30: Asset
B31: =C31&D31&E31 -> 1218101 | C31: 121 | D31: 81 | E31: 01 | F31: Chứng khoán và công cụ tài chính khác | G31: 3 | K31: Asset
B32: =C32&D32&E32 -> 1280000 | C32: 128 | D32: 00 | E32: 00 | F32: Đầu tư nắm giữ đến ngày đáo hạn | G32: 1 | H32: x | K32: Asset
B33: =C33&D33&E33 -> 1281000 | C33: 128 | D33: 10 | E33: 00 | F33: Tiền gửi có kỳ hạn | G33: 2 | H33: x | K33: Asset
B34: =C34&D34&E34 -> 1281101 | C34: 128 | D34: 11 | E34: 01 | F34: Tiền gửi có kỳ hạn dưới 3 tháng | G34: 3 | I34: BS112 | K34: Asset | L34: Supplier
B35: =C35&D35&E35 -> 1281102 | C35: 128 | D35: 11 | E35: 02 | F35: Tiền gửi có kỳ hạn trên 3 tháng đến 12 tháng | G35: 3 | I35: BS123 | K35: Asset | L35: Supplier
B36: =C36&D36&E36 -> 1283000 | C36: 128 | D36: 30 | E36: 00 | F36: Cho vay | G36: 2 | H36: x | I36: BS135 | K36: Asset
B37: =C37&D37&E37 -> 1283101 | C37: 128 | D37: 31 | E37: 01 | F37: Cho vay | G37: 3 | K37: Asset | L37: Supplier
B38: =C38&D38&E38 -> 1310000 | C38: 131 | D38: 00 | E38: 00 | F38: Phải thu khách hàng | G38: 1 | H38: x | K38: Asset
B39: =C39&D39&E39 -> 1311000 | C39: 131 | D39: 10 | E39: 00 | F39: Phải thu khách hàng | G39: 2 | H39: x | I39: BS131 | K39: Asset
B40: =C40&D40&E40 -> 1311101 | C40: 131 | D40: 11 | E40: 01 | F40: Phải thu khách hàng | G40: 3 | K40: Asset | L40: Customer
B41: =C41&D41&E41 -> 1312000 | C41: 131 | D41: 20 | E41: 00 | F41: Khách hàng trả tiền trước | G41: 2 | H41: x | J41: BS312
B42: =C42&D42&E42 -> 1312101 | C42: 131 | D42: 21 | E42: 01 | F42: Khách hàng trả tiền trước | G42: 3 | K42: Asset | L42: Customer
...

Sheet Seg 2 TK Ngoại bảng
A1: Tài khoản Ngoài bảng
A3: Số tài khoản | B3: Tên tài khoản | C3: Parent
A4: 001 | B4: Tài sản thuê ngoài
A5: 002 | B5: Vật tư, hàng hoá nhận giữ hộ, nhận gia công
A6: 003 | B6: Hàng hoá nhận bán hộ, nhận ký gửi, ký cược
A7: 004 | B7: Nợ khó đòi đã xử lý
A8: 007 | B8: Ngoại tệ các loại
A9: 008 | B9: Dự toán chi sự nghiệp, dự án

Sheet Seg 3 - Sub Acc
A1: Segment 3 : xx.xxx(Chi tiết tài khoản - Sub Account)
A2: Biến phí, Định phí có thể Group theo Nhóm chi phí không, để đưa vào PL theo Group chi phí | J2: Check Ngân sách: YTD-QTD
A3: Mã | B3: Giá trị | C3: Nhóm | D3: Parent | E3: Level | F3: Thuộc tài khoản | G3: Mã Cost center | H3: Tên Cost center | I3: Check thực hiện và KH | J3: Budget control (Y/N) | K3: ĐP/BP | L3: Lập PR (Y/N) | M3: Ghi chú
A4: 11000 | B4: TIỀN MẶT | C4: BS | D4: x | E4: 1
A5: 11001 | B5: TM-HCM | C5: BS | E5: 2 | F5: ='Seg 2_Account'!B8 -> 1111101
A6: =A5+1 -> 11002 | B6: TM-NHA TRANG | C6: BS | E6: 2 | F6: =$F$5 -> 1111101
A7: =A6+1 -> 11003 | B7: TM-ĐẮC LẮC | C7: BS | E7: 2 | F7: =$F$5 -> 1111101
A8: =A7+1 -> 11004 | B8: TM-ĐÀ NẴNG | C8: BS | E8: 2 | F8: =$F$5 -> 1111101
A9: =A8+1 -> 11005 | B9: TM-HÀ NỘI | C9: BS | E9: 2 | F9: =$F$5 -> 1111101
A10: =A9+1 -> 11006 | B10: TM-CẦN THƠ | C10: BS | E10: 2 | F10: =$F$5 -> 1111101
A11: 12000 | B11: NGÂN HÀNG | C11: BS | D11: x | E11: 1
A12: 12001 | B12: VTB-KHANHHOA-VND-8467 | C12: BS | E12: 2 | F12: ='Seg 2_Account'!B13 -> 1121101
A13: =A12+1 -> 12002 | B13: VCB-KHANHHOA-VND-5620 | C13: BS | E13: 2 | F13: ='Seg 2_Account'!B14 -> 1121102
A14: =A13+1 -> 12003 | B14: VCB-HOANGVANTHU-VND-0750 | C14: BS | E14: 2 | F14: =$F$13 -> 1121102
A15: =A14+1 -> 12004 | B15: VCB-DANANG-VND-3063 | C15: BS | E15: 2 | F15: =$F$13 -> 1121102
A16: =A15+1 -> 12005 | B16: VCB-DAKLAK-VND-6693 | C16: BS | E16: 2 | F16: =$F$13 -> 1121102
A17: =A16+1 -> 12006 | B17: VCB-HANOI-VND-0515 | C17: BS | E17: 2 | F17: =$F$13 -> 1121102
A18: =A17+1 -> 12007 | B18: VCB-KHANHHOA-USD-7004 | C18: BS | E18: 2 | F18: ='Seg 2_Account'!B16 -> 1122101
A19: 24000 | B19: Xây dựng cơ bản dở dang | C19: BS | D19: x | E19: 1 | M19: Trong SubAccount, nếu cần theo dõi tập hợp chi phí xây dựng theo từng đối tượng như Kho Tân Thuận, Kho Đà Nẵng…thì sẽ thực hiện thế nào?
A20: 24001 | B20: Tủ đông | C20: BS | E20: 2 | F20: ='Seg 2_Account'!$B$177 -> 2411101 | G20: =#REF! -> #REF! | H20: =VLOOKUP($G20,#REF!,2,0) -> #REF! | I20: x | J20: Y | L20: Y | N20: Updated 16/10/2024
A21: =A20+1 -> 24002 | B21: Kho | C21: BS | E21: 2 | F21: ='Seg 2_Account'!B180 -> 2412101 | G21: =#REF! -> #REF! | H21: =VLOOKUP($G21,#REF!,2,0) -> #REF! | I21: x | J21: Y | L21: Y | N21: Updated 16/10/2024
A22: =A21+1 -> 24003 | B22: Phần mềm | C22: BS | E22: 2 | F22: =$F$21 -> 2412101 | G22: All | H22: All (except BP Ban điều hành) | I22: x | J22: Y | L22: Y | N22: Updated 16/10/2024
A23: =A22+1 -> 24004 | B23: Quyền sử dụng đất | C23: BS | E23: 2 | F23: =$F$21 -> 2412101 | I23: x
A24: =A23+1 -> 24005 | B24: Phương tiện vận tải | C24: BS | E24: 2 | F24: ='Seg 2_Account'!$B$177 -> 2411101 | G24: =#REF! -> #REF! | H24: =VLOOKUP($G24,#REF!,2,0) -> #REF! | I24: x | J24: Y | L24: Y | N24: Updated 16/10/2024
A25: 51000 | B25: Doanh thu hoạt động tài chính | C25: PL1 | D25: x | E25: 1
A26: 51001 | B26: Lãi cho Cá nhân vay | C26: PL1 | E26: 2 | F26: ='Seg 2_Account'!B373 -> 5152000
A27: =A26+1 -> 51002 | B27: Lãi cho Công ty vay | C27: PL1 | E27: 2 | F27: =$F$26 -> 5152000
A28: =A27+1 -> 51003 | B28: Lãi trả chậm, trả góp | C28: PL1 | E28: 2 | F28: =$F$26 -> 5152000
A29: =A28+1 -> 51004 | B29: Thu nhập về hoạt động đầu tư mua, bán chứng khoán | C29: PL1 | E29: 2 | F29: =$F$26 -> 5152000
A30: =A29+1 -> 51005 | B30: Lãi từ hoạt động chuyển nhượng vốn | C30: PL1 | E30: 2 | F30: =$F$26 -> 5152000
A31: =A30+1 -> 51006 | B31: Thu nhập về các hoạt động đầu tư khác | C31: PL1 | E31: 2 | F31: =$F$26 -> 5152000
A32: =A31+1 -> 51007 | B32: Lãi tỷ giá hối đoái | C32: PL1 | E32: 2 | F32: ='Seg 2_Account'!$B$375&", "&'Seg 2_Account'!$B$376 -> 5152102, 5153000
A33: =A32+1 -> 51008 | B33: Chiết khấu thanh toán được hưởng từ NCC | C33: PL1 | E33: 2 | F33: ='Seg 2_Account'!B378 -> 5158000
A34: =A33+1 -> 51009 | B34: Lãi tiền gửi ngân hàng | C34: PL1 | E34: 2 | F34: ='Seg 2_Account'!B380 -> 5210000
A35: 51999 | B35: Doanh thu hoạt động tài chính khác | C35: PL1 | E35: 2 | F35: =F34 -> 5210000
A36: 52000 | B36: Chi phí hoạt động tài chính | C36: PL1 | D36: x | E36: 1
A37: 52001 | B37: Chi phí lãi vay Cá nhân | C37: PL1 | E37: 2 | F37: ='Seg 2_Account'!B414 -> 6351000 | I37: x | M37: Có cần tách không?
A38: =A37+1 -> 52002 | B38: Chi phí lãi vay Tổ chức tín dụng | C38: PL1 | E38: 2 | F38: =$F$37 -> 6351000 | I38: x | M38: Có cần tách không?
A39: =A38+1 -> 52003 | B39: Lỗ tỷ giá hối đoái | C39: PL1 | E39: 2 | F39: ='Seg 2_Account'!B416&","& 'Seg 2_Account'!B417 -> 6352000,6352101 | I39: x
A40: =A39+1 -> 52004 | B40: Chiết khấu thanh toán cho khách hàng | C40: PL1 | E40: 2 | F40: ='Seg 2_Account'!B419 -> 6353000 | I40: x
...

Sheet Seg 4_Cost center-DeptSite1
A2: Segment 4: x.xx.xx (Cost Center) | J2: Mã Khối.Mã Bộ phận.Mã Site
A4: Mã Khối | B4: Tên Khối | C4: Mã Bộ phận | D4: Tên BP | E4: Mã Site | F4: Tên site | G4: Ký hiệu site | H4: Mã COA | I4: Diễn giải | J4: Parent | K4: level
C5: 0000 | H5: 0000 | I5: Mặc định
A6: 1 | B6: Khối Trực tiếp | H6: 10000 | I6: Khối Trực Tiếp | J6: x | K6: 1
C7: 111 | D7: Bộ phận Kinh doanh | H7: =C7&"00" -> 11100 | I7: =D7 -> Bộ phận Kinh doanh | K7: 2
C8: =$C$7 -> 111 | D8: Bộ phận Kinh doanh | E8: 10 | F8: =VLOOKUP($E8,'Bo phan'!$B$31:$D$39,2,0) -> Hồ Chí Minh | G8: =VLOOKUP($E8,'Bo phan'!$B$31:$D$39,3,0) -> HCM | H8: =C8&E8 -> 11110 | I8: =G8&"."&D8 -> HCM.Bộ phận Kinh doanh | K8: 3
C9: =$C$7 -> 111 | D9: Bộ phận Kinh doanh | E9: 20 | F9: =VLOOKUP(E9,'Bo phan'!$B$31:$D$39,2,0) -> Nha Trang | G9: =VLOOKUP($E9,'Bo phan'!$B$31:$D$39,3,0) -> NTR | H9: =C9&E9 -> 11120 | I9: =G9&"."&D9 -> NTR.Bộ phận Kinh doanh | K9: 3
C10: =$C$7 -> 111 | D10: Bộ phận Kinh doanh | E10: 30 | F10: =VLOOKUP(E10,'Bo phan'!$B$31:$D$39,2,0) -> Đắc Lắc | G10: =VLOOKUP($E10,'Bo phan'!$B$31:$D$39,3,0) -> DLA | H10: =C10&E10 -> 11130 | I10: =G10&"."&D10 -> DLA.Bộ phận Kinh doanh | K10: 3
C11: =$C$7 -> 111 | D11: Bộ phận Kinh doanh | E11: 40 | F11: =VLOOKUP(E11,'Bo phan'!$B$31:$D$39,2,0) -> Đà Nẵng | G11: =VLOOKUP($E11,'Bo phan'!$B$31:$D$39,3,0) -> DNG | H11: =C11&E11 -> 11140 | I11: =G11&"."&D11 -> DNG.Bộ phận Kinh doanh | K11: 3
C12: =$C$7 -> 111 | D12: Bộ phận Kinh doanh | E12: 50 | F12: =VLOOKUP(E12,'Bo phan'!$B$31:$D$39,2,0) -> Hà Nội | G12: =VLOOKUP($E12,'Bo phan'!$B$31:$D$39,3,0) -> HNO | H12: =C12&E12 -> 11150 | I12: =G12&"."&D12 -> HNO.Bộ phận Kinh doanh | K12: 3
C13: =$C$7 -> 111 | D13: Bộ phận Kinh doanh | E13: 60 | F13: =VLOOKUP(E13,'Bo phan'!$B$31:$D$39,2,0) -> Cần Thơ | G13: =VLOOKUP($E13,'Bo phan'!$B$31:$D$39,3,0) -> CTH | H13: =C13&E13 -> 11160 | I13: =G13&"."&D13 -> CTH.Bộ phận Kinh doanh | K13: 3
C14: 112 | D14: Bộ phận Logistic - Quản lý | H14: =C14&"00" -> 11200 | I14: =D14 -> Bộ phận Logistic - Quản lý | K14: 2
C15: =$C$14 -> 112 | D15: Bộ phận Logistic - Quản lý | E15: 10 | F15: =VLOOKUP($E15,'Bo phan'!$B$31:$D$39,2,0) -> Hồ Chí Minh | G15: =VLOOKUP($E15,'Bo phan'!$B$31:$D$39,3,0) -> HCM | H15: =C15&E15 -> 11210 | I15: =G15&"."&D15 -> HCM.Bộ phận Logistic - Quản lý | K15: 3
C16: =$C$14 -> 112 | D16: Bộ phận Logistic - Quản lý | E16: 20 | F16: =VLOOKUP(E16,'Bo phan'!$B$31:$D$39,2,0) -> Nha Trang | G16: =VLOOKUP($E16,'Bo phan'!$B$31:$D$39,3,0) -> NTR | H16: =C16&E16 -> 11220 | I16: =G16&"."&D16 -> NTR.Bộ phận Logistic - Quản lý | K16: 3
C17: =$C$14 -> 112 | D17: Bộ phận Logistic - Quản lý | E17: 30 | F17: =VLOOKUP(E17,'Bo phan'!$B$31:$D$39,2,0) -> Đắc Lắc | G17: =VLOOKUP($E17,'Bo phan'!$B$31:$D$39,3,0) -> DLA | H17: =C17&E17 -> 11230 | I17: =G17&"."&D17 -> DLA.Bộ phận Logistic - Quản lý | K17: 3
C18: =$C$14 -> 112 | D18: Bộ phận Logistic - Quản lý | E18: 40 | F18: =VLOOKUP(E18,'Bo phan'!$B$31:$D$39,2,0) -> Đà Nẵng | G18: =VLOOKUP($E18,'Bo phan'!$B$31:$D$39,3,0) -> DNG | H18: =C18&E18 -> 11240 | I18: =G18&"."&D18 -> DNG.Bộ phận Logistic - Quản lý | K18: 3
C19: =$C$14 -> 112 | D19: Bộ phận Logistic - Quản lý | E19: 50 | F19: =VLOOKUP(E19,'Bo phan'!$B$31:$D$39,2,0) -> Hà Nội | G19: =VLOOKUP($E19,'Bo phan'!$B$31:$D$39,3,0) -> HNO | H19: =C19&E19 -> 11250 | I19: =G19&"."&D19 -> HNO.Bộ phận Logistic - Quản lý | K19: 3
C20: =$C$14 -> 112 | D20: Bộ phận Logistic - Quản lý | E20: 60 | F20: =VLOOKUP(E20,'Bo phan'!$B$31:$D$39,2,0) -> Cần Thơ | G20: =VLOOKUP($E20,'Bo phan'!$B$31:$D$39,3,0) -> CTH | H20: =C20&E20 -> 11260 | I20: =G20&"."&D20 -> CTH.Bộ phận Logistic - Quản lý | K20: 3
C21: 113 | D21: Bộ phận Logistic - Kho | H21: =C21&"00" -> 11300 | I21: =D21 -> Bộ phận Logistic - Kho | J21: x | K21: 2
C22: =$C$21 -> 113 | D22: Bộ phận Logistic - Kho | E22: 10 | F22: =VLOOKUP($E22,'Bo phan'!$B$31:$D$39,2,0) -> Hồ Chí Minh | G22: =VLOOKUP($E22,'Bo phan'!$B$31:$D$39,3,0) -> HCM | H22: =C22&E22 -> 11310 | I22: =G22&"."&D22 -> HCM.Bộ phận Logistic - Kho | K22: 3
C23: =$C$21 -> 113 | D23: Bộ phận Logistic - Kho | E23: 20 | F23: =VLOOKUP(E23,'Bo phan'!$B$31:$D$39,2,0) -> Nha Trang | G23: =VLOOKUP($E23,'Bo phan'!$B$31:$D$39,3,0) -> NTR | H23: =C23&E23 -> 11320 | I23: =G23&"."&D23 -> NTR.Bộ phận Logistic - Kho | K23: 3
C24: =$C$21 -> 113 | D24: Bộ phận Logistic - Kho | E24: 30 | F24: =VLOOKUP(E24,'Bo phan'!$B$31:$D$39,2,0) -> Đắc Lắc | G24: =VLOOKUP($E24,'Bo phan'!$B$31:$D$39,3,0) -> DLA | H24: =C24&E24 -> 11330 | I24: =G24&"."&D24 -> DLA.Bộ phận Logistic - Kho | K24: 3
C25: =$C$21 -> 113 | D25: Bộ phận Logistic - Kho | E25: 40 | F25: =VLOOKUP(E25,'Bo phan'!$B$31:$D$39,2,0) -> Đà Nẵng | G25: =VLOOKUP($E25,'Bo phan'!$B$31:$D$39,3,0) -> DNG | H25: =C25&E25 -> 11340 | I25: =G25&"."&D25 -> DNG.Bộ phận Logistic - Kho | K25: 3
C26: =$C$21 -> 113 | D26: Bộ phận Logistic - Kho | E26: 50 | F26: =VLOOKUP(E26,'Bo phan'!$B$31:$D$39,2,0) -> Hà Nội | G26: =VLOOKUP($E26,'Bo phan'!$B$31:$D$39,3,0) -> HNO | H26: =C26&E26 -> 11350 | I26: =G26&"."&D26 -> HNO.Bộ phận Logistic - Kho | K26: 3
C27: =$C$21 -> 113 | D27: Bộ phận Logistic - Kho | E27: 60 | F27: =VLOOKUP(E27,'Bo phan'!$B$31:$D$39,2,0) -> Cần Thơ | G27: =VLOOKUP($E27,'Bo phan'!$B$31:$D$39,3,0) -> CTH | H27: =C27&E27 -> 11360 | I27: =G27&"."&D27 -> CTH.Bộ phận Logistic - Kho | K27: 3
C28: 114 | D28: Bộ phận Logistic - Giao nhận | H28: =C28&"00" -> 11400 | I28: =D28 -> Bộ phận Logistic - Giao nhận | J28: x | K28: 2
C29: =$C$28 -> 114 | D29: Bộ phận Logistic - Giao nhận | E29: 10 | F29: =VLOOKUP($E29,'Bo phan'!$B$31:$D$39,2,0) -> Hồ Chí Minh | G29: =VLOOKUP($E29,'Bo phan'!$B$31:$D$39,3,0) -> HCM | H29: =C29&E29 -> 11410 | I29: =G29&"."&D29 -> HCM.Bộ phận Logistic - Giao nhận | K29: 3
C30: =$C$28 -> 114 | D30: Bộ phận Logistic - Giao nhận | E30: 20 | F30: =VLOOKUP(E30,'Bo phan'!$B$31:$D$39,2,0) -> Nha Trang | G30: =VLOOKUP($E30,'Bo phan'!$B$31:$D$39,3,0) -> NTR | H30: =C30&E30 -> 11420 | I30: =G30&"."&D30 -> NTR.Bộ phận Logistic - Giao nhận | K30: 3
C31: =$C$28 -> 114 | D31: Bộ phận Logistic - Giao nhận | E31: 30 | F31: =VLOOKUP(E31,'Bo phan'!$B$31:$D$39,2,0) -> Đắc Lắc | G31: =VLOOKUP($E31,'Bo phan'!$B$31:$D$39,3,0) -> DLA | H31: =C31&E31 -> 11430 | I31: =G31&"."&D31 -> DLA.Bộ phận Logistic - Giao nhận | K31: 3
C32: =$C$28 -> 114 | D32: Bộ phận Logistic - Giao nhận | E32: 40 | F32: =VLOOKUP(E32,'Bo phan'!$B$31:$D$39,2,0) -> Đà Nẵng | G32: =VLOOKUP($E32,'Bo phan'!$B$31:$D$39,3,0) -> DNG | H32: =C32&E32 -> 11440 | I32: =G32&"."&D32 -> DNG.Bộ phận Logistic - Giao nhận | K32: 3
C33: =$C$28 -> 114 | D33: Bộ phận Logistic - Giao nhận | E33: 50 | F33: =VLOOKUP(E33,'Bo phan'!$B$31:$D$39,2,0) -> Hà Nội | G33: =VLOOKUP($E33,'Bo phan'!$B$31:$D$39,3,0) -> HNO | H33: =C33&E33 -> 11450 | I33: =G33&"."&D33 -> HNO.Bộ phận Logistic - Giao nhận | K33: 3
C34: =$C$28 -> 114 | D34: Bộ phận Logistic - Giao nhận | E34: 60 | F34: =VLOOKUP(E34,'Bo phan'!$B$31:$D$39,2,0) -> Cần Thơ | G34: =VLOOKUP($E34,'Bo phan'!$B$31:$D$39,3,0) -> CTH | H34: =C34&E34 -> 11460 | I34: =G34&"."&D34 -> CTH.Bộ phận Logistic - Giao nhận | K34: 3
C35: 115 | D35: Bộ phận Marketing | H35: =C35&"00" -> 11500 | I35: =D35 -> Bộ phận Marketing | J35: x | K35: 2
C36: =$C$35 -> 115 | D36: Bộ phận Marketing | E36: 10 | F36: =VLOOKUP($E36,'Bo phan'!$B$31:$D$39,2,0) -> Hồ Chí Minh | G36: =VLOOKUP($E36,'Bo phan'!$B$31:$D$39,3,0) -> HCM | H36: =C36&E36 -> 11510 | I36: =G36&"."&D36 -> HCM.Bộ phận Marketing | K36: 3
C37: =$C$35 -> 115 | D37: Bộ phận Marketing | E37: 20 | F37: =VLOOKUP(E37,'Bo phan'!$B$31:$D$39,2,0) -> Nha Trang | G37: =VLOOKUP($E37,'Bo phan'!$B$31:$D$39,3,0) -> NTR | H37: =C37&E37 -> 11520 | I37: =G37&"."&D37 -> NTR.Bộ phận Marketing | K37: 3
C38: =$C$35 -> 115 | D38: Bộ phận Marketing | E38: 30 | F38: =VLOOKUP(E38,'Bo phan'!$B$31:$D$39,2,0) -> Đắc Lắc | G38: =VLOOKUP($E38,'Bo phan'!$B$31:$D$39,3,0) -> DLA | H38: =C38&E38 -> 11530 | I38: =G38&"."&D38 -> DLA.Bộ phận Marketing | K38: 3
C39: =$C$35 -> 115 | D39: Bộ phận Marketing | E39: 40 | F39: =VLOOKUP(E39,'Bo phan'!$B$31:$D$39,2,0) -> Đà Nẵng | G39: =VLOOKUP($E39,'Bo phan'!$B$31:$D$39,3,0) -> DNG | H39: =C39&E39 -> 11540 | I39: =G39&"."&D39 -> DNG.Bộ phận Marketing | K39: 3
C40: =$C$35 -> 115 | D40: Bộ phận Marketing | E40: 50 | F40: =VLOOKUP(E40,'Bo phan'!$B$31:$D$39,2,0) -> Hà Nội | G40: =VLOOKUP($E40,'Bo phan'!$B$31:$D$39,3,0) -> HNO | H40: =C40&E40 -> 11550 | I40: =G40&"."&D40 -> HNO.Bộ phận Marketing | K40: 3
C41: =$C$35 -> 115 | D41: Bộ phận Marketing | E41: 60 | F41: =VLOOKUP(E41,'Bo phan'!$B$31:$D$39,2,0) -> Cần Thơ | G41: =VLOOKUP($E41,'Bo phan'!$B$31:$D$39,3,0) -> CTH | H41: =C41&E41 -> 11560 | I41: =G41&"."&D41 -> CTH.Bộ phận Marketing | K41: 3
C42: 116 | D42: Bộ phận Trade Marketing | H42: =C42&"00" -> 11600 | I42: =D42 -> Bộ phận Trade Marketing | J42: x | K42: 2
...

Sheet Seg 6_Khu vực
B1: Segment 6 : xxxx (Khu vực - Area)
B3: Value | C3: Description | D3: Parent | E3: Level
B4: 0000 | C4: Mặc định | E4: 1
B5: 1000 | C5: Miền Nam | D5: x | E5: 1
B6: 1100 | C6: Hồ Chí Minh | D6: x | E6: 2
B7: 1101 | C7: Hồ Chí Minh | E7: 3
B8: 1200 | C8: Đông Nam Bộ | D8: x | E8: 2
B9: 1201 | C9: Bình Dương | E9: 3
B10: 1202 | C10: Vũng Tàu | E10: 3
B11: 1300 | C11: Tây Nam Bộ | D11: x | E11: 2
B12: 1301 | C12: Long An | E12: 3
B13: 1302 | C13: Đồng Nai | E13: 3
B14: 1303 | C14: Bến Tre
B15: 2000 | C15: Miền Bắc | D15: x | E15: 1
B16: 2100 | C16: Hà Nội | D16: x | E16: 2
B17: 2101 | C17: Hà Nội | E17: 3
B18: 2200 | C18: Đồng bằng Bắc Bộ | D18: x | E18: 2
B19: 2201 | C19: Bắc Ninh | E19: 3
B20: 2202 | C20: Hải Dương | E20: 3
B21: 2203 | C21: Hải Phòng | E21: 3
B22: 2204 | C22: Vĩnh Phúc | E22: 3
B23: 2300 | C23: Đông Bắc Bộ | D23: x | E23: 2
B24: 2301 | C24: Quảng Ninh | E24: 3
B25: 2302 | C25: Thái Nguyên | E25: 3
B27: 3000 | C27: Miền Trung & Tây Nguyên | D27: x | E27: 1
B28: 3100 | C28: Bắc Trung Bộ | D28: x | E28: 2
B29: 3101 | C29: Thanh Hóa | E29: 3
B30: 3200 | C30: Nam Trung Bộ | D30: x | E30: 2
B31: 3300 | C31: Tây Nguyên | D31: x | E31: 2
B32: 4000 | C32: Online | D32: x | E32: 1
B33: 4100 | C33: Online | D33: x | E33: 2
B34: 4101 | C34: Online | E34: 3

Sheet Seg 4_Location
A2: Segment 4 : x.xx.xx.xx.xx.xx (Vị trí - Location) | C2: Mã quốc gia. Mã miền.Mã vùng. Mã tỉnh thành. Mã quận huyện. Mã phường xã
A4: Mã | B4: Giá trị | C4: Parent | D4: Level
B5: Mặc định | D5: 1
B6: Kết chuyển | D6: 1
B7: Việt Nam | C7: x | D7: 1
B8: Miền Nam | C8: x | D8: 2
B9: Đông Nam Bộ | C9: x | D9: 3
B10: Hồ Chí Minh | C10: x | D10: 4
B11: Quận 1 | D11: 5
B12: Quận 2 | D12: 5
B13: Bình Dương | C13: x | D13: 4
B14: Thành phố Thủ Dầu Một | D14: 5
B15: Thành phố Dĩ An | D15: 5
B16: Đồng Nai | C16: x | D16: 4
B17: Thành phố Biên Hòa | D17: 5
B18: Huyện Thống Nhất | D18: 5
B19: Thành phố Vũng Tàu | C19: x | D19: 4
B20: Phường Thắng Nhất | D20: 5
B21: Phường Thắng Nhì | D21: 5
B22: Tây Nam Bộ | C22: x | D22: 3
B23: Long An | C23: x | D23: 4
B24: Thành phố Tân An | D24: 5
B25: Huyện Tân Hưng | D25: 5
B26: Tiền Giang | C26: x | D26: 4
B27: Thành phố Mỹ Tho | D27: 5
B28: Huyện Chợ Gạo | D28: 5
B29: Thành phố Cần Thơ | C29: x | D29: 4
B30: Quận Ninh Kiều | D30: 5
B31: Quận Cái Răng | D31: 5
B32: Miền Trung | C32: x | D32: 2
B33: Bắc Trung Bộ | C33: x | D33: 3
B34: Nghệ An | D34: 4
B35: Thanh Hóa | D35: 4
B36: Hà Tĩnh | D36: 4
B37: Quảng Bình | D37: 4
B38: Quảng Trị | D38: 4
B39: Thừa Thiên-Huế | D39: 4
B40: Nam Trung Bộ | C40: x | D40: 3
B41: Đà Nẵng | D41: 4
B42: Khánh Hoà | D42: 4
...

Sheet Seg 4_Cost center-SiteDept
A2: Segment 4: xx.xx (Phòng ban - Cost Center) | F2: Mã Site. Mã Bộ phận
A4: Mã Site | B4: Mã Bộ phận | C4: Tên BP | D4: Mã COA | E4: Diễn giải | F4: Parent | G4: level
A5: 0000 | B5: 0000 | D5: 0000 | E5: Mặc định
A6: 10 | B6: 00 | D6: 1000 | E6: HỒ CHÍ MINH | F6: x | G6: 1
A7: =$A$6 -> 10 | B7: 11 | C7: =VLOOKUP(B7,'[1]Bo phan'!$B$5:$C$25,2,0) -> Bộ phận Ban Điều hành | D7: =A7&B7 -> 1011 | E7: ="HCM."&C7 -> HCM.Bộ phận Ban Điều hành | G7: 2
A8: =$A$6 -> 10 | B8: =B7+1 -> 12 | C8: =VLOOKUP(B8,'[1]Bo phan'!$B$5:$C$25,2,0) -> Bộ phận Kinh doanh | D8: =A8&B8 -> 1012 | E8: ="HCM."&C8 -> HCM.Bộ phận Kinh doanh | G8: 2
A9: =$A$6 -> 10 | B9: =B8+1 -> 13 | C9: =VLOOKUP(B9,'[1]Bo phan'!$B$5:$C$25,2,0) -> Bộ phận Logistic - Quản lý | D9: =A9&B9 -> 1013 | E9: ="HCM."&C9 -> HCM.Bộ phận Logistic - Quản lý | G9: 2
A10: =$A$6 -> 10 | B10: =B9+1 -> 14 | C10: =VLOOKUP(B10,'[1]Bo phan'!$B$5:$C$25,2,0) -> Bộ phận Logistic - Kho | D10: =A10&B10 -> 1014 | E10: ="HCM."&C10 -> HCM.Bộ phận Logistic - Kho | G10: 2
A11: =$A$6 -> 10 | B11: =B10+1 -> 15 | C11: =VLOOKUP(B11,'[1]Bo phan'!$B$5:$C$25,2,0) -> Bộ phận Logistic - Giao nhận | D11: =A11&B11 -> 1015 | E11: ="HCM."&C11 -> HCM.Bộ phận Logistic - Giao nhận | G11: 2
A12: =$A$6 -> 10 | B12: =B11+1 -> 16 | C12: =VLOOKUP(B12,'[1]Bo phan'!$B$5:$C$25,2,0) -> Bộ phận Marketing | D12: =A12&B12 -> 1016 | E12: ="HCM."&C12 -> HCM.Bộ phận Marketing | G12: 2
A13: =$A$6 -> 10 | B13: =B12+1 -> 17 | C13: =VLOOKUP(B13,'[1]Bo phan'!$B$5:$C$25,2,0) -> Bộ phận Trade Marketing | D13: =A13&B13 -> 1017 | E13: ="HCM."&C13 -> HCM.Bộ phận Trade Marketing | G13: 2
A14: =$A$6 -> 10 | B14: =B13+1 -> 18 | C14: =VLOOKUP(B14,'[1]Bo phan'!$B$5:$C$25,2,0) -> Bộ phận Tài chính - Kế toán | D14: =A14&B14 -> 1018 | E14: ="HCM."&C14 -> HCM.Bộ phận Tài chính - Kế toán | G14: 2
A15: =$A$6 -> 10 | B15: =B14+1 -> 19 | C15: =VLOOKUP(B15,'[1]Bo phan'!$B$5:$C$25,2,0) -> Bộ phận Hành chính - Nhân sự | D15: =A15&B15 -> 1019 | E15: ="HCM."&C15 -> HCM.Bộ phận Hành chính - Nhân sự | G15: 2
A16: =$A$6 -> 10 | B16: =B15+1 -> 20 | C16: =VLOOKUP(B16,'[1]Bo phan'!$B$5:$C$25,2,0) -> Bộ phận Kế hoạch | D16: =A16&B16 -> 1020 | E16: ="HCM."&C16 -> HCM.Bộ phận Kế hoạch | G16: 2
A17: =$A$6 -> 10 | B17: =B16+1 -> 21 | C17: =VLOOKUP(B17,'[1]Bo phan'!$B$5:$C$25,2,0) -> Bộ phận Xuất nhập khẩu | D17: =A17&B17 -> 1021 | E17: ="HCM."&C17 -> HCM.Bộ phận Xuất nhập khẩu | G17: 2
A18: =$A$6 -> 10 | B18: =B17+1 -> 22 | C18: =VLOOKUP(B18,'[1]Bo phan'!$B$5:$C$25,2,0) -> Bộ phận Sourcing | D18: =A18&B18 -> 1022 | E18: ="HCM."&C18 -> HCM.Bộ phận Sourcing | G18: 2
A19: =$A$6 -> 10 | B19: =B18+1 -> 23 | C19: =VLOOKUP(B19,'[1]Bo phan'!$B$5:$C$25,2,0) -> Bộ phận Mua hàng | D19: =A19&B19 -> 1023 | E19: ="HCM."&C19 -> HCM.Bộ phận Mua hàng | G19: 2
... A24: =$A$6 -> 10 | B24: =B23+1 -> 28 | C24: =VLOOKUP(B24,'[1]Bo phan'!$B$5:$C$25,2,0) -> Bộ phận chung | D24: =A24&B24 -> 1028 | E24: ="HCM."&C24 -> HCM.Bộ phận chung | G24: 2
A25: 20 | B25: 00 | D25: 2000 | E25: NHA TRANG | F25: x | G25: 1
A26: =$A$25 -> 20 | B26: 11 | C26: =VLOOKUP(B26,'[1]Bo phan'!$B$5:$C$25,2,0) -> Bộ phận Ban Điều hành | D26: =A26&B26 -> 2011 | E26: ="NTR."&C26 -> NTR.Bộ phận Ban Điều hành | G26: 2
A27: =$A$25 -> 20 | B27: =B26+1 -> 12 | C27: =VLOOKUP(B27,'[1]Bo phan'!$B$5:$C$25,2,0) -> Bộ phận Kinh doanh | D27: =A27&B27 -> 2012 | E27: ="NTR."&C27 -> NTR.Bộ phận Kinh doanh | G27: 2
A28: =$A$25 -> 20 | B28: =B27+1 -> 13 | C28: =VLOOKUP(B28,'[1]Bo phan'!$B$5:$C$25,2,0) -> Bộ phận Logistic - Quản lý | D28: =A28&B28 -> 2013 | E28: ="NTR."&C28 -> NTR.Bộ phận Logistic - Quản lý | G28: 2
A29: =$A$25 -> 20 | B29: =B28+1 -> 14 | C29: =VLOOKUP(B29,'[1]Bo phan'!$B$5:$C$25,2,0) -> Bộ phận Logistic - Kho | D29: =A29&B29 -> 2014 | E29: ="NTR."&C29 -> NTR.Bộ phận Logistic - Kho | G29: 2
A30: =$A$25 -> 20 | B30: =B29+1 -> 15 | C30: =VLOOKUP(B30,'[1]Bo phan'!$B$5:$C$25,2,0) -> Bộ phận Logistic - Giao nhận | D30: =A30&B30 -> 2015 | E30: ="NTR."&C30 -> NTR.Bộ phận Logistic - Giao nhận | G30: 2
A31: =$A$25 -> 20 | B31: =B30+1 -> 16 | C31: =VLOOKUP(B31,'[1]Bo phan'!$B$5:$C$25,2,0) -> Bộ phận Marketing | D31: =A31&B31 -> 2016 | E31: ="NTR."&C31 -> NTR.Bộ phận Marketing | G31: 2
A32: =$A$25 -> 20 | B32: =B31+1 -> 17 | C32: =VLOOKUP(B32,'[1]Bo phan'!$B$5:$C$25,2,0) -> Bộ phận Trade Marketing | D32: =A32&B32 -> 2017 | E32: ="NTR."&C32 -> NTR.Bộ phận Trade Marketing | G32: 2
A33: =$A$25 -> 20 | B33: =B32+1 -> 18 | C33: =VLOOKUP(B33,'[1]Bo phan'!$B$5:$C$25,2,0) -> Bộ phận Tài chính - Kế toán | D33: =A33&B33 -> 2018 | E33: ="NTR."&C33 -> NTR.Bộ phận Tài chính - Kế toán | G33: 2
A34: =$A$25 -> 20 | B34: =B33+1 -> 19 | C34: =VLOOKUP(B34,'[1]Bo phan'!$B$5:$C$25,2,0) -> Bộ phận Hành chính - Nhân sự | D34: =A34&B34 -> 2019 | E34: ="NTR."&C34 -> NTR.Bộ phận Hành chính - Nhân sự | G34: 2
A35: =$A$25 -> 20 | B35: =B34+1 -> 20 | C35: =VLOOKUP(B35,'[1]Bo phan'!$B$5:$C$25,2,0) -> Bộ phận Kế hoạch | D35: =A35&B35 -> 2020 | E35: ="NTR."&C35 -> NTR.Bộ phận Kế hoạch | G35: 2
A36: =$A$25 -> 20 | B36: =B35+1 -> 21 | C36: =VLOOKUP(B36,'[1]Bo phan'!$B$5:$C$25,2,0) -> Bộ phận Xuất nhập khẩu | D36: =A36&B36 -> 2021 | E36: ="NTR."&C36 -> NTR.Bộ phận Xuất nhập khẩu | G36: 2
A37: =$A$25 -> 20 | B37: =B36+1 -> 22 | C37: =VLOOKUP(B37,'[1]Bo phan'!$B$5:$C$25,2,0) -> Bộ phận Sourcing | D37: =A37&B37 -> 2022 | E37: ="NTR."&C37 -> NTR.Bộ phận Sourcing | G37: 2
A38: =$A$25 -> 20 | B38: =B37+1 -> 23 | C38: =VLOOKUP(B38,'[1]Bo phan'!$B$5:$C$25,2,0) -> Bộ phận Mua hàng | D38: =A38&B38 -> 2023 | E38: ="NTR."&C38 -> NTR.Bộ phận Mua hàng | G38: 2
... A43: =$A$25 -> 20 | B43: =B42+1 -> 28 | C43: =VLOOKUP(B43,'[1]Bo phan'!$B$5:$C$25,2,0) -> Bộ phận chung | D43: =A43&B43 -> 2028 | E43: ="NTR."&C43 -> NTR.Bộ phận chung | G43: 2
A44: 30 | D44: 3000 | E44: ĐẮC LẮC | F44: x | G44: 1
A45: =$A$44 -> 30 | B45: 11 | C45: =VLOOKUP(B45,'[1]Bo phan'!$B$5:$C$25,2,0) -> Bộ phận Ban Điều hành | D45: =A45&B45 -> 3011 | E45: ="DLA."&C45 -> DLA.Bộ phận Ban Điều hành | G45: 2
A46: =$A$44 -> 30 | B46: =B45+1 -> 12 | C46: =VLOOKUP(B46,'[1]Bo phan'!$B$5:$C$25,2,0) -> Bộ phận Kinh doanh | D46: =A46&B46 -> 3012 | E46: ="DLA."&C46 -> DLA.Bộ phận Kinh doanh | G46: 2
A47: =$A$44 -> 30 | B47: =B46+1 -> 13 | C47: =VLOOKUP(B47,'[1]Bo phan'!$B$5:$C$25,2,0) -> Bộ phận Logistic - Quản lý | D47: =A47&B47 -> 3013 | E47: ="DLA."&C47 -> DLA.Bộ phận Logistic - Quản lý | G47: 2
A48: =$A$44 -> 30 | B48: =B47+1 -> 14 | C48: =VLOOKUP(B48,'[1]Bo phan'!$B$5:$C$25,2,0) -> Bộ phận Logistic - Kho | D48: =A48&B48 -> 3014 | E48: ="DLA."&C48 -> DLA.Bộ phận Logistic - Kho | G48: 2
A49: =$A$44 -> 30 | B49: =B48+1 -> 15 | C49: =VLOOKUP(B49,'[1]Bo phan'!$B$5:$C$25,2,0) -> Bộ phận Logistic - Giao nhận | D49: =A49&B49 -> 3015 | E49: ="DLA."&C49 -> DLA.Bộ phận Logistic - Giao nhận | G49: 2
A50: =$A$44 -> 30 | B50: =B49+1 -> 16 | C50: =VLOOKUP(B50,'[1]Bo phan'!$B$5:$C$25,2,0) -> Bộ phận Marketing | D50: =A50&B50 -> 3016 | E50: ="DLA."&C50 -> DLA.Bộ phận Marketing | G50: 2
...

Sheet Bank R
A1: Viết tắt | B1: Bank | C1: Branch | D1: Cost center | E1: Account | H1: 62000 | I1: Chi phí bao bì, vật tư
A2: Vietinbank | B2: NGÂN HÀNG TMCP CÔNG THƯƠNG VN | C2: CN KHANH HOA | D2: Nha Trang | E2: 110002918467 | F2: VND | H2: 63000 | I2: Chi phí công cụ, dụng cụ, đồ dùng
H3: 64000 | I3: Chi phí khấu hao
A4: VCB | B4: NGÂN HÀNG NGOẠI THƯƠNG VN | C4: CN HOANG VAN THU | D4: HCM | E4: 1024910750 | F4: VND | H4: 65000 | I4: Chi phí thuế, phí
C5: CN KHANH HOA | D5: Nha Trang | E5: 1025805620 | F5: VND | H5: 66000 | I5: Chi phí hỗ trợ bán hàng
C6: CN DA NANG | D6: Đà Nẵng | E6: 1025853063 | F6: VND | H6: 67100 | I6: Chi phí vận chuyển
C7: CN Dak Lak | D7: Dak Lak | E7: 1025916693 | F7: VND | H7: 67200 | I7: Chi phí thuê kho
C8: CN HA NOI | D8: Hà Nội | E8: 1026160515 | F8: VND | H8: 67300 | I8: Chi phí dịch vụ mua ngoài
C9: CN KHANH HOA | D9: Nha Trang | E9: 1027287004 | F9: USD | H9: 68000 | I9: Chi phí khác
A10: MB | B10: NGÂN HÀNG TMCP QUÂN ĐỘI
A11: BIDV | B11: NGÂN HÀNG TMCP ĐẦU TƯ & PHÁT TRIỂN VN
A12: ACB | B12: NGÂN HÀNG TMCP Á CHÂU
A13: TCB | B13: NGÂN HÀNG TMCP KỸ THƯƠNG VN
A14: ABBANK | B14: NGÂN HÀNG TM CP AN BÌNH
A15: MSB | B15: NGÂN HÀNG TM CP HÀNG HẢI VIỆT NAM
A16: BVB | B16: NGÂN HÀNG TMCP BẢO VIỆT
A17: Vietinbank | B17: NGÂN HÀNG TMCP CÔNG THƯƠNG
A18: SeABank | B18: NGÂN HÀNG TMCP ĐÔNG NAM Á ( SEABANK)
A19: NamA Bank | B19: NGÂN HÀNG TMCP NAM Á
A20: VDB | B20: NGÂN HÀNG TMCP PHÁT TRIỂN TP.HCM
A21: OCB | B21: NGÂN HÀNG TMCP PHƯƠNG ĐÔNG
... A28: HSBC | B28: NGÂN HÀNG TNHH MTV HSBC

Sheet Bo phan
A2: DANH MỤC BỘ PHẬN QUẢN LÝ
C5: Tên Khối/ Bộ phận/ Site | D5: Ghi chú
B6: 1 | C6: Khối trực tiếp
B7: 2 | C7: Khối gián tiếp
C11: Bộ phận Ban Điều hành
C12: Bộ phận Kinh doanh
C13: Bộ phận Logistic - Quản lý
C14: Bộ phận Logistic - Kho
C15: Bộ phận Logistic - Giao nhận | D15: Hiện nay đang theo dõi chi tiết theo từng xe tải
C16: Bộ phận Marketing
C17: Bộ phận Trade Marketing
C18: Bộ phận Tài chính - Kế toán
C19: Bộ phận Hành chính - Nhân sự
C20: Bộ phận Kế hoạch
C21: Bộ phận Xuất nhập khẩu
C22: Bộ phận Sourcing
C23: Bộ phận Mua hàng
C24: Bộ phận Công nghệ thông tin
C25: Bộ phận Nghiên cứu phát triển
C26: Bộ phận Bảo trì - Kỹ thuật - Cơ điện
C27: Bộ phận QA-QC-ATTP-LAB
C28: Bộ phận chung
B31: Mã Site | C31: Tên site | D31: Ký hiệu
B32: 10 | C32: Hồ Chí Minh | D32: HCM
B33: 20 | C33: Nha Trang | D33: NTR
B34: 30 | C34: Đắc Lắc | D34: DLA
B35: 40 | C35: Đà Nẵng | D35: DNG
B36: 50 | C36: Hà Nội | D36: HNO
B37: 60 | C37: Cần Thơ | D37: CTH
B46: Mã Bộ phận | C46: Tên bộ phận hiện tại
B47: 1000 | C47: Bộ phận Ban Điều hành
B48: 1001 | C48: Bộ phận Kinh doanh Trực tiếp
B49: 1002 | C49: Bộ phận Kinh doanh Gián tiếp
B50: 1003 | C50: Bộ phận Marketing
B51: 1004 | C51: Bộ phận Trade Marketing
B52: 1005 | C52: Bộ phận Tài chính - Kế toán
B53: 1006 | C53: Bộ phận Hành chính - Nhân sự
B54: 1007 | C54: Bộ phận Kế hoạch
B55: 1008 | C55: Bộ phận Xuất nhập khẩu
B56: 1009 | C56: Bộ phận Sourcing - Mua hàng
...
